<?xml version="1.0" encoding="UTF-8"?>

<robot xmlns:xacro="http://www.ros.org/wiki/xacro" name="arduinobot">
    <xacro:include filename="$(find robot_description)/urdf/robot_gazebo.xacro"/>
    <xacro:include filename="$(find robot_description)/urdf/robot_ros2_control.xacro"/>

    <xacro:property name="effort" value="30.0"/>
    <xacro:property name="velocity" value="10.0"/>
    <xacro:macro name="default_inertial" params="mass">
        <inertial>
            <mass value="${mass}"/>
            <inertia ixx="1.0" ixy="0.0" ixz="0.0"
                     iyy="1.0" iyz="0.0"
                     izz="1.0"/>
        </inertial>
    </xacro:macro>
    <xacro:macro name="default_transmission" params="number">
        <transmission name="transmission_${number}">
            <plugin>transmission_interface/SimpleTransmission</plugin>
            <actuator name="motor_${number}" role="actuator1"/>
            <joint name="joint_${number}" role="joint1">
                <mechanical_reduction>1.0</mechanical_reduction>
            </joint>
        </transmission>
    </xacro:macro>
    <link name="world"/>
    <link name="base_link">
        <visual>
            <geometry>
                <mesh filename="package://robot_description/meshes/basement.STL" scale="0.01 0.01 0.01"/>
            </geometry>
            <origin xyz="-0.5 -0.5 0" rpy="0 0 0"/>
        </visual>
        <collision>
            <geometry>
                <mesh filename="package://robot_description/meshes/basement.STL" scale="0.01 0.01 0.01"/>
            </geometry>
            <origin xyz="-0.5 -0.5 0" rpy="0 0 0"/>
        </collision>
        <xacro:default_inertial mass="1.0"/>
    </link>
    <joint name="virtual_joint" type="fixed">
        <parent link="world"/>
        <child link="base_link"/>
        <origin xyz="0 0 0" rpy="0 0 0"/>
    </joint>

    <link name="base_plate">
        <visual>
            <geometry>
                <mesh filename="package://robot_description/meshes/base_plate.STL" scale="0.01 0.01 0.01"/>
            </geometry>
            <origin rpy="0 0 0" xyz="-0.39 -0.39 -0.56"/>
        </visual>
        <collision>
            <geometry>
                <mesh filename="package://robot_description/meshes/base_plate.STL" scale="0.01 0.01 0.01"/>
            </geometry>
            <origin rpy="0 0 0" xyz="-0.39 -0.39 -0.56"/>
        </collision>
        <xacro:default_inertial mass="1.0"/>
    </link>
    <joint name="joint_1" type="revolute">
        <parent link="base_link"/>
        <child link="base_plate"/>
        <axis xyz="0 0 1"/>
        <origin rpy="0 0 0" xyz="0 0 0.307"/>
        <limit lower="-${pi/2}" upper="${pi/2}" effort="${effort}" velocity="${velocity}"/>
    </joint>

    <link name="forward_drive_arm">
        <visual>
            <geometry>
                <mesh filename="package://robot_description/meshes/forward_drive_arm.STL" scale="0.01 0.01 0.01"/>
            </geometry>
            <origin rpy="0 -${pi/2} ${pi/2}" xyz="0.19 0.06 -0.08"/>
        </visual>
        <collision>
            <geometry>
                <mesh filename="package://robot_description/meshes/forward_drive_arm.STL" scale="0.01 0.01 0.01"/>
            </geometry>
            <origin rpy="0 -${pi/2} ${pi/2}" xyz="0.19 0.06 -0.08"/>
        </collision>
        <xacro:default_inertial mass="1.0"/>
    </link>

    <joint name="joint_2" type="revolute">
        <parent link="base_plate"/>
        <child link="forward_drive_arm"/>
        <axis xyz="1 0 0"/>
        <origin rpy="0 0 0" xyz="-0.02 0 0.35"/>
        <limit lower="-${pi/2}" upper="${pi/2}" effort="${effort}" velocity="${velocity}"/>
    </joint>

    <link name="horizontal_arm">
        <visual>
            <geometry>
                <mesh filename="package://robot_description/meshes/horizontal_arm.STL" scale="0.01 0.01 0.01"/>
            </geometry>
            <origin rpy="${pi/2} 0 ${pi/2}" xyz="-0.03 -0.4 -0.06"/>
        </visual>
        <collision>
            <geometry>
                <mesh filename="package://robot_description/meshes/horizontal_arm.STL" scale="0.01 0.01 0.01"/>
            </geometry>
            <origin rpy="${pi/2} 0 ${pi/2}" xyz="-0.03 -0.4 -0.06"/>

        </collision>
        <xacro:default_inertial mass="1.0"/>
    </link>
    <joint name="joint_3" type="revolute">
        <parent link="forward_drive_arm"/>
        <child link="horizontal_arm"/>
        <axis xyz="1 0 0"/>
        <origin rpy="0 0 0" xyz="0 0 0.8"/>
        <limit lower="-${pi/2}" upper="${pi/2}" effort="${effort}" velocity="${velocity}"/>
    </joint>

    <link name="claw_support">
        <visual>
            <geometry>
                <mesh filename="package://robot_description/meshes/claw_support.STL" scale="0.01 0.01 0.01"/>
            </geometry>
            <origin rpy="0 0 ${pi/2}" xyz="0 -0.05 -0.15"/>
        </visual>
        <collsion>
            <geometry>
                <mesh filename="package://robot_description/meshes/claw_support.STL" scale="0.01 0.01 0.01"/>
            </geometry>
            <origin rpy="0 0 ${pi/2}" xyz="0 -0.05 -0.15"/>
        </collsion>
        <xacro:default_inertial mass="0.05"/>
    </link>
    <joint name="horizontal_arm_to_claw_support" type="fixed">
        <parent link="horizontal_arm"/>
        <child link="claw_support"/>
        <origin rpy="0 0 0" xyz="0 0.82 0"/>
    </joint>

    <link name="gripper_right">
        <visual>
            <geometry>
                <mesh filename="package://robot_description/meshes/right_finger.STL" scale="0.01 0.01 0.01"/>
            </geometry>
            <origin xyz="-0.1 0.5 -0.1" rpy="0 0 -${pi/2}"/>
        </visual>
        <collision>
            <geometry>
                <mesh filename="package://robot_description/meshes/right_finger.STL" scale="0.01 0.01 0.01"/>
            </geometry>
            <origin xyz="-0.1 0.5 -0.1" rpy="0 0 -${pi/2}"/>
        </collision>
        <xacro:default_inertial mass="0.01"/>
    </link>
    <link name="gripper_left">
        <visual>
            <geometry>
                <mesh filename="package://robot_description/meshes/left_finger.STL" scale="0.01 0.01 0.01"/>
            </geometry>
            <origin xyz="-0.04 0.5 -0.1" rpy="0 0 -${pi/2}"/>
        </visual>
        <collision>
            <geometry>
                <mesh filename="package://robot_description/meshes/left_finger.STL" scale="0.01 0.01 0.01"/>
            </geometry>
            <origin xyz="-0.04 0.5 -0.1" rpy="0 0 -${pi/2}"/>
        </collision>
        <xacro:default_inertial mass="0.01"/>
    </link>
    <joint name="joint_4" type="revolute">
        <parent link="claw_support"/>
        <child link="gripper_right"/>
        <origin xyz="-0.04 0.13 -0.1" rpy="0 0 0"/>
        <axis xyz="0 0 1"/>
        <limit lower="-${pi/2}" upper="0" effort="${effort}" velocity="${velocity}"/>
    </joint>
    <joint name="joint_5" type="revolute">
        <parent link="claw_support"/>
        <child link="gripper_left"/>
        <origin xyz="-0.22 0.13 -0.1" rpy="0 0 0"/>
        <axis xyz="0 0 1"/>
        <mimic joint="joint_4" multiplier="-1"/>
        <limit lower="0" upper="${pi/2}" effort="${effort}" velocity="${velocity}"/>
    </joint>
    <xacro:default_transmission number="1"/>
    <xacro:default_transmission number="2"/>
    <xacro:default_transmission number="3"/>
    <xacro:default_transmission number="4"/>
</robot>